<?xml version='1.0'?>
<robot name="my_robot" xmlns:xacro="https://www.ros.org/wiki/xacro">
    <!-- include gazebo plugin file -->
    <xacro:include filename="$(find my_robot)/urdf/my_robot.gazebo"/>
    <xacro:include filename="$(find my_robot)/urdf/materials.xacro"/>
    <!-- link robot_footprint -->
    <link name="robot_footprint"></link>

    <!-- link left_wheel -->
    <link name="left_wheel">
        <inertial>
            <mass value="5"/>
            <inertia
                ixx="0.1" ixy="0" ixz="0"
                iyy="0.1" iyz="0"
                izz="0.1"
                />
        </inertial>
        <collision name="left_collision">
            <origin xyz="0 0 0" rpy="0 1.5707 1.5707"/>
            <geometry>
                <cylinder radius="0.1" length="0.05"/>
            </geometry>
        </collision>
        <visual name="left_visual">
            <origin xyz="0 0 0" rpy="0 1.5707 1.5707"/>
            <geometry>
                <cylinder radius="0.1" length="0.05"/>
            </geometry>
            <material name="green"/>
        </visual>
    </link>

    <!-- link right_wheel -->
    <link name="right_wheel">
        <inertial>
            <mass value="5"/>
            <inertia
                ixx="0.1" ixy="0" ixz="0"
                iyy="0.1" iyz="0"
                izz="0.1"
                />
        </inertial>
        <collision name="right_collision">
            <origin xyz="0 0 0" rpy="0 1.5707 1.5707"/>
            <geometry>
                <cylinder radius="0.1" length="0.05"/>
            </geometry>
        </collision>
        <visual name="right_visual">
            <origin xyz="0 0 0" rpy="0 1.5707 1.5707"/>
            <geometry>
                <cylinder radius="0.1" length="0.05"/>
            </geometry>
        </visual>
    </link>

    <!-- link camera -->
    <link name='camera'>
        <inertial>
            <mass value="0.1"/>
            <inertia
                ixx="1e-6" ixy="0" ixz="0"
                iyy="1e-6" iyz="0"
                izz="1e-6"
                />
        </inertial>
        <collision name="camera_collision">
            <origin xyz="0 0 0" rpy="0 0 0"/>
            <geometry>
                <box size=".05 .05 .05"/>
            </geometry>
        </collision>
        <visual>
            <origin xyz="0 0 0" rpy="0 0 0"/>
            <geometry>
                <box size=".05 .05 .05"/>
            </geometry>
        </visual>
    </link>

    <!-- link hokuyo -->
    <link name="hokuyo">
        <inertial>
            <mass value="1e-5"/>
            <inertia
                ixx="1e-6" ixy="0" ixz="0"
                iyy="1e-6" iyz="0"
                izz="0"
                />
        </inertial>
        <collision>
            <origin xyz="0 0 0" rpy="0 0 0"/>
            <geometry>
                <box size="0.1 0.1 0.1"/>
            </geometry>
        </collision>
        <visual>
            <origin xyz="0 0 0" rpy="0 0 0"/>
            <geometry>
                <mesh filename="package://my_robot/meshes/hokuyo.dae"/>
            </geometry>
        </visual>
    </link>

    <!-- joint hokuyo_joint -->
    <joint name="hokuyo_joint" type="fixed" >
        <origin xyz="0.15 0 0.1" rpy="0 0 0"/>
        <parent link="chassis"/>
        <child link="hokuyo"/>
        <axis xyz="0 0 1"/>
    </joint> -->

    <!-- joint camera_joint -->
    <joint name="camera_joint" type="fixed" >
        <origin xyz="0.2 0 0" rpy="0 0 0"/>
        <parent link="chassis"/>
        <child link="camera"/>
        <axis xyz="0 1 0" rpy="0 0 0"/>
    </joint>

    <!-- joint robot_footprint_joint -->
    <joint name="robot_footprint_joint" type="fixed">
        <origin xyz="0 0 0" rpy="0 0 0"/>
        <parent link="robot_footprint"/>
        <child link="chassis"/>
    </joint>
    
    <!-- joint left_wheel_hinge-->
    <joint type="continuous" name="left_wheel_hinge" >
        <origin xyz="0 0.15 0" rpy="0 0 0"/>
        <child link="left_wheel"/>
        <parent link="chassis"/>
        <axis xyz="0 1 0" rpy="0 0 0"/>
        <limit effort="1000" velocity="1000"/>
        <dynamics damping="1.0" friction="1.0"/>
    </joint>

    <!-- joint right_wheel_hinge-->
    <joint type="continuous" name="right_wheel_hinge" >
        <origin xyz="0 -0.15 0" rpy="0 0 0"/>
        <child link="right_wheel"/>
        <parent link="chassis"/>
        <axis xyz="0 1 0" rpy="0 0 0"/>
        <limit effort="1000" velocity="1000"/>
        <dynamics damping="1.0" friction="1.0"/>
    </joint>

    <!-- link chassis -->
    <link name='chassis'>
        <pose>0 0 0.1 0 0 0</pose>
        <inertial>
            <mass value="15.0"/>
            <origin xyz="0.0 0 0" rpy="0 0 0"/>
            <inertia
                ixx="0.1" ixy="0" ixz="0"
                iyy="0.1" iyz="0"
                izz="0.1"
                />
        </inertial>
        <collision name='collision'>
            <origin xyz="0 0 0" rpy="0 0 0"/>
            <geometry>
                <box size=".4 .2 .1"/>
            </geometry>
        </collision>
        <visual name='chassis_visual'>
            <origin xyz="0 0 0" rpy="0 0 0"/>
            <geometry>
                <box size=".4 .2 .1"/>
            </geometry>
        </visual>
        <collision name='back_caster_collision'>
            <origin xyz ="-0.15 0 -0.05" rpy=" 0 0 0"/>
            <geometry>
                <sphere radius="0.0499"/>
            </geometry>
        </collision>
        <visual name='back_caster_visual'>
            <origin xyz ="-0.15 0 -0.05" rpy=" 0 0 0"/>
            <geometry>
                <sphere radius="0.05"/>
            </geometry>
        </visual>
        <collision name='front_caster_collision'>
            <origin xyz="0.15 0 -0.05" rpy=" 0 0 0"/>
            <geometry>
                <sphere radius="0.0499"/>
            </geometry>
        </collision>
        <visual name='front_caster_visual'>
            <origin xyz="0.15 0 -0.05"/>
            <geometry>
                <sphere radius="0.05"/>
            </geometry>
        </visual>
    </link>

</robot>
    
        
